Workbook
Name Slicer_Exited1: #N/A
Name Slicer_Geography: #N/A

Sheet Customer-Churn-Records
A1: RowNumber | B1: CustomerId | C1: Surname | D1: CreditScore | E1: Geography | F1: Gender | G1: Age | H1: Tenure | I1: Balance | J1: NumOfProducts | K1: HasCrCard | L1: IsActiveMember | M1: EstimatedSalary | N1: Exited | O1: Complain | P1: Satisfaction Score | Q1: Card Type | R1: Point Earned | S1: Column1
A2: 1 | B2: 15634602 | C2: Hargrave | D2: 619 | E2: France | F2: Female | G2: 42 | H2: 2 | I2: 0 | J2: 1 | K2: =VLOOKUP($U2,DIC!$E$3:$F$4,2,FALSE) -> YES | L2: =VLOOKUP(V2,DIC!$E$3:$F$4,2,FALSE) -> YES | M2: 101348.88 | N2: =VLOOKUP(W2,DIC!$E$3:$F$4,2,FALSE) -> YES | O2: =VLOOKUP(X2,DIC!$E$3:$F$4,2,FALSE) -> YES | P2: =VLOOKUP(Y2,DIC!$B$3:$C$7,2,FALSE) -> NOT SATISFIED | Q2: DIAMOND | R2: 464 | U2: 1 | V2: 1 | W2: 1 | X2: 1 | Y2: 2
A3: 2 | B3: 15647311 | C3: Hill | D3: 608 | E3: Spain | F3: Female | G3: 41 | H3: 1 | I3: 83807.86 | J3: 1 | K3: =VLOOKUP($U3,DIC!$E$3:$F$4,2,FALSE) -> NO | L3: =VLOOKUP(V3,DIC!$E$3:$F$4,2,FALSE) -> YES | M3: 112542.58 | N3: =VLOOKUP(W3,DIC!$E$3:$F$4,2,FALSE) -> NO | O3: =VLOOKUP(X3,DIC!$E$3:$F$4,2,FALSE) -> YES | P3: =VLOOKUP(Y3,DIC!$B$3:$C$7,2,FALSE) -> AVERAGE | Q3: DIAMOND | R3: 456 | U3: 0 | V3: 1 | W3: 0 | X3: 1 | Y3: 3
A4: 3 | B4: 15619304 | C4: Onio | D4: 502 | E4: France | F4: Female | G4: 42 | H4: 8 | I4: 159660.8 | J4: 3 | K4: =VLOOKUP($U4,DIC!$E$3:$F$4,2,FALSE) -> YES | L4: =VLOOKUP(V4,DIC!$E$3:$F$4,2,FALSE) -> NO | M4: 113931.57 | N4: =VLOOKUP(W4,DIC!$E$3:$F$4,2,FALSE) -> YES | O4: =VLOOKUP(X4,DIC!$E$3:$F$4,2,FALSE) -> YES | P4: =VLOOKUP(Y4,DIC!$B$3:$C$7,2,FALSE) -> AVERAGE | Q4: DIAMOND | R4: 377 | U4: 1 | V4: 0 | W4: 1 | X4: 1 | Y4: 3
A5: 4 | B5: 15701354 | C5: Boni | D5: 699 | E5: France | F5: Female | G5: 39 | H5: 1 | I5: 0 | J5: 2 | K5: =VLOOKUP($U5,DIC!$E$3:$F$4,2,FALSE) -> NO | L5: =VLOOKUP(V5,DIC!$E$3:$F$4,2,FALSE) -> NO | M5: 93826.63 | N5: =VLOOKUP(W5,DIC!$E$3:$F$4,2,FALSE) -> NO | O5: =VLOOKUP(X5,DIC!$E$3:$F$4,2,FALSE) -> NO | P5: =VLOOKUP(Y5,DIC!$B$3:$C$7,2,FALSE) -> EXCELLENT | Q5: GOLD | R5: 350 | U5: 0 | V5: 0 | W5: 0 | X5: 0 | Y5: 5
A6: 5 | B6: 15737888 | C6: Mitchell | D6: 850 | E6: Spain | F6: Female | G6: 43 | H6: 2 | I6: 125510.82 | J6: 1 | K6: =VLOOKUP($U6,DIC!$E$3:$F$4,2,FALSE) -> YES | L6: =VLOOKUP(V6,DIC!$E$3:$F$4,2,FALSE) -> YES | M6: 79084.1 | N6: =VLOOKUP(W6,DIC!$E$3:$F$4,2,FALSE) -> NO | O6: =VLOOKUP(X6,DIC!$E$3:$F$4,2,FALSE) -> NO | P6: =VLOOKUP(Y6,DIC!$B$3:$C$7,2,FALSE) -> EXCELLENT | Q6: GOLD | R6: 425 | U6: 1 | V6: 1 | W6: 0 | X6: 0 | Y6: 5
A7: 6 | B7: 15574012 | C7: Chu | D7: 645 | E7: Spain | F7: Male | G7: 44 | H7: 8 | I7: 113755.78 | J7: 2 | K7: =VLOOKUP($U7,DIC!$E$3:$F$4,2,FALSE) -> YES | L7: =VLOOKUP(V7,DIC!$E$3:$F$4,2,FALSE) -> NO | M7: 149756.71 | N7: =VLOOKUP(W7,DIC!$E$3:$F$4,2,FALSE) -> YES | O7: =VLOOKUP(X7,DIC!$E$3:$F$4,2,FALSE) -> YES | P7: =VLOOKUP(Y7,DIC!$B$3:$C$7,2,FALSE) -> EXCELLENT | Q7: DIAMOND | R7: 484 | U7: 1 | V7: 0 | W7: 1 | X7: 1 | Y7: 5
A8: 7 | B8: 15592531 | C8: Bartlett | D8: 822 | E8: France | F8: Male | G8: 50 | H8: 7 | I8: 0 | J8: 2 | K8: =VLOOKUP($U8,DIC!$E$3:$F$4,2,FALSE) -> YES | L8: =VLOOKUP(V8,DIC!$E$3:$F$4,2,FALSE) -> YES | M8: 10062.8 | N8: =VLOOKUP(W8,DIC!$E$3:$F$4,2,FALSE) -> NO | O8: =VLOOKUP(X8,DIC!$E$3:$F$4,2,FALSE) -> NO | P8: =VLOOKUP(Y8,DIC!$B$3:$C$7,2,FALSE) -> NOT SATISFIED | Q8: SILVER | R8: 206 | U8: 1 | V8: 1 | W8: 0 | X8: 0 | Y8: 2
A9: 8 | B9: 15656148 | C9: Obinna | D9: 376 | E9: Germany | F9: Female | G9: 29 | H9: 4 | I9: 115046.74 | J9: 4 | K9: =VLOOKUP($U9,DIC!$E$3:$F$4,2,FALSE) -> YES | L9: =VLOOKUP(V9,DIC!$E$3:$F$4,2,FALSE) -> NO | M9: 119346.88 | N9: =VLOOKUP(W9,DIC!$E$3:$F$4,2,FALSE) -> YES | O9: =VLOOKUP(X9,DIC!$E$3:$F$4,2,FALSE) -> YES | P9: =VLOOKUP(Y9,DIC!$B$3:$C$7,2,FALSE) -> NOT SATISFIED | Q9: DIAMOND | R9: 282 | U9: 1 | V9: 0 | W9: 1 | X9: 1 | Y9: 2
A10: 9 | B10: 15792365 | C10: He | D10: 501 | E10: France | F10: Male | G10: 44 | H10: 4 | I10: 142051.07 | J10: 2 | K10: =VLOOKUP($U10,DIC!$E$3:$F$4,2,FALSE) -> NO | L10: =VLOOKUP(V10,DIC!$E$3:$F$4,2,FALSE) -> YES | M10: 74940.5 | N10: =VLOOKUP(W10,DIC!$E$3:$F$4,2,FALSE) -> NO | O10: =VLOOKUP(X10,DIC!$E$3:$F$4,2,FALSE) -> NO | P10: =VLOOKUP(Y10,DIC!$B$3:$C$7,2,FALSE) -> AVERAGE | Q10: GOLD | R10: 251 | U10: 0 | V10: 1 | W10: 0 | X10: 0 | Y10: 3
A11: 10 | B11: 15592389 | C11: H? | D11: 684 | E11: France | F11: Male | G11: 27 | H11: 2 | I11: 134603.88 | J11: 1 | K11: =VLOOKUP($U11,DIC!$E$3:$F$4,2,FALSE) -> YES | L11: =VLOOKUP(V11,DIC!$E$3:$F$4,2,FALSE) -> YES | M11: 71725.73 | N11: =VLOOKUP(W11,DIC!$E$3:$F$4,2,FALSE) -> NO | O11: =VLOOKUP(X11,DIC!$E$3:$F$4,2,FALSE) -> NO | P11: =VLOOKUP(Y11,DIC!$B$3:$C$7,2,FALSE) -> AVERAGE | Q11: GOLD | R11: 342 | U11: 1 | V11: 1 | W11: 0 | X11: 0 | Y11: 3
A12: 11 | B12: 15767821 | C12: Bearce | D12: 528 | E12: France | F12: Male | G12: 31 | H12: 6 | I12: 102016.72 | J12: 2 | K12: =VLOOKUP($U12,DIC!$E$3:$F$4,2,FALSE) -> NO | L12: =VLOOKUP(V12,DIC!$E$3:$F$4,2,FALSE) -> NO | M12: 80181.12 | N12: =VLOOKUP(W12,DIC!$E$3:$F$4,2,FALSE) -> NO | O12: =VLOOKUP(X12,DIC!$E$3:$F$4,2,FALSE) -> NO | P12: =VLOOKUP(Y12,DIC!$B$3:$C$7,2,FALSE) -> AVERAGE | Q12: GOLD | R12: 264 | U12: 0 | V12: 0 | W12: 0 | X12: 0 | Y12: 3
A13: 12 | B13: 15737173 | C13: Andrews | D13: 497 | E13: Spain | F13: Male | G13: 24 | H13: 3 | I13: 0 | J13: 2 | K13: =VLOOKUP($U13,DIC!$E$3:$F$4,2,FALSE) -> YES | L13: =VLOOKUP(V13,DIC!$E$3:$F$4,2,FALSE) -> NO | M13: 76390.01 | N13: =VLOOKUP(W13,DIC!$E$3:$F$4,2,FALSE) -> NO | O13: =VLOOKUP(X13,DIC!$E$3:$F$4,2,FALSE) -> NO | P13: =VLOOKUP(Y13,DIC!$B$3:$C$7,2,FALSE) -> AVERAGE | Q13: GOLD | R13: 249 | U13: 1 | V13: 0 | W13: 0 | X13: 0 | Y13: 3
... A10001: 10000 | B10001: 15628319 | C10001: Walker | D10001: 792 | E10001: France | F10001: Female | G10001: 28 | H10001: 4 | I10001: 130142.79 | J10001: 1 | K10001: =VLOOKUP($U10001,DIC!$E$3:$F$4,2,FALSE) -> YES | L10001: =VLOOKUP(V10001,DIC!$E$3:$F$4,2,FALSE) -> NO | M10001: 38190.78 | N10001: =VLOOKUP(W10001,DIC!$E$3:$F$4,2,FALSE) -> NO | O10001: =VLOOKUP(X10001,DIC!$E$3:$F$4,2,FALSE) -> NO | P10001: =VLOOKUP(Y10001,DIC!$B$3:$C$7,2,FALSE) -> AVERAGE | Q10001: DIAMOND | R10001: 911 | U10001: 1 | V10001: 0 | W10001: 0 | X10001: 0 | Y10001: 3

Sheet DIC
B3: 1 | C3: BAD | E3: 1 | F3: YES
B4: 2 | C4: NOT SATISFIED | E4: 0 | F4: NO
B5: 3 | C5: AVERAGE
B6: 4 | C6: GOOD
B7: 5 | C7: EXCELLENT

Sheet PIVOT TABLE
D3: COUNT | F3: FEMALE AND MALE | I3: AGE WISE | M3: HAS CARDS | P3: ACTIVR MEMBER | S3: CARD VS INCOME GROUP
D4: Count of RowNumber | F4: Row Labels | G4: Count of RowNumber | I4: Row Labels | J4: Count of RowNumber | M4: Row Labels | N4: Count of HasCrCard | P4: Row Labels | Q4: Count of IsActiveMember | S4: Count of HasCrCard | T4: Column Labels | X4: LEFT
D5: 10000 | F5: Female | G5: 0.4543 | I5: 18-27 | J5: 1020 | M5: NO | N5: 2945 | P5: NO | Q5: 0.4849 | S5: Row Labels | T5: YES | Y5: Column Labels | AH5: AVERAGE SALARY OF EXIT | AK5: COMPLAIN VS LEFT | AP5: SATIFACATION VS LEFT | BD5: FOR PRESENTATION
F6: Male | G6: 0.5457 | I6: 28-37 | J6: 4067 | M6: YES | N6: 7055 | P6: YES | Q6: 0.5151 | S6: 100011.58-105011.58 | T6: 207 | Y6: NO | Z6: YES | AA6: Grand Total | AH6: Row Labels | AI6: Average of EstimatedSalary | AK6: Count of Complain | AL6: Column Labels | AP6: Row Labels | AQ6: Count of Exited | AU6: POINT EARNED VS LEFT
F7: Grand Total | G7: 1 | I7: 38-47 | J7: 3203 | M7: Grand Total | N7: 10000 | P7: Grand Total | Q7: 1 | S7: 55011.58-60011.58 | T7: 191 | X7: Count of Exited | Y7: 0.7962 | Z7: 0.2038 | AA7: 1 | AH7: NO | AI7: 99726.853 | AK7: Row Labels | AL7: NO | AM7: YES | AN7: Grand Total | AP7: AVERAGE | AQ7: 2042 | AU7: Row Labels | AV7: Average of Balance | BD7: Row Labels | BE7: Average of Balance
I8: 48-57 | J8: 1055 | S8: 45011.58-50011.58 | T8: 191 | AH8: YES | AI8: 101509.91 | AK8: NO | AL8: 0.99949723 | AM8: 0.00050276521 | AN8: 1 | AP8: BAD | AQ8: 1932 | AU8: NO | AV8: 72742.751 | BD8: 11.58-5011.58 | BE8: 67614.507 | BI8: Count of Exited | BJ8: Column Labels
I9: 58-67 | J9: 463 | S9: 175011.58-180011.58 | T9: 190 | AC9: AVERAGE SALARY OF EXIT | AH9: Grand Total | AI9: 100090.24 | AK9: YES | AL9: 0.0048923679 | AM9: 0.99510763 | AN9: 1 | AP9: EXCELLENT | AQ9: 2004 | AU9: YES | AV9: 91109.476 | BD9: 5011.58-10011.58 | BE9: 73208.164 | BI9: Row Labels | BJ9: NO | BK9: YES | BL9: Grand Total
I10: 68-77 | J10: 168 | S10: 25011.58-30011.58 | T10: 189 | AC10: Row Labels | AD10: Count of Exited | AK10: Grand Total | AL10: 0.7962 | AM10: 0.2038 | AN10: 1 | AP10: GOOD | AQ10: 2008 | AU10: Grand Total | AV10: 76485.889 | BD10: 10011.58-15011.58 | BE10: 68302.82 | BI10: NO | BJ10: 2332 | BK10: 613 | BL10: 2945
I11: 78-87 | J11: 21 | S11: 90011.58-95011.58 | T11: 189 | AC11: France | AD11: 5014 | AP11: NOT SATISFIED | AQ11: 2014 | BD11: 15011.58-20011.58 | BE11: 78994.468 | BI11: YES | BJ11: 5630 | BK11: 1425 | BL11: 7055
I12: 88-97 | J12: 3 | S12: 70011.58-75011.58 | T12: 187 | AC12: Germany | AD12: 2509 | AP12: Grand Total | AQ12: 10000 | BD12: 20011.58-25011.58 | BE12: 84714.769 | BI12: Grand Total | BJ12: 7962 | BK12: 2038 | BL12: 10000
D13: CREDIT SCORE VS LRFTT | I13: Grand Total | J13: 10000 | S13: 60011.58-65011.58 | T13: 186 | AC13: Spain | AD13: 2477 | BD13: 25011.58-30011.58 | BE13: 73533.286
D14: Row Labels | E14: Count of Exited | S14: 115011.58-120011.58 | T14: 185 | AC14: Grand Total | AD14: 10000 | AK14: COMPLAIN VS COUNTRY | BD14: 30011.58-35011.58 | BE14: 76602.54
D15: 350-399 | E15: 19 | S15: 125011.58-130011.58 | T15: 185 | AK15: Count of Complain | AL15: Column Labels | BD15: 35011.58-40011.58 | BE15: 76973.152
D16: 400-449 | E16: 166 | S16: 11.58-5011.58 | T16: 185 | AK16: Row Labels | AL16: YES | AM16: Grand Total | BD16: 40011.58-45011.58 | BE16: 77131.231
D17: 450-499 | E17: 447 | J17: NUM OF PRODUCTS | S17: 170011.58-175011.58 | T17: 184 | AK17: Germany | AL17: 0.40068493 | AM17: 0.40068493 | AP17: CARD TYPE VS LEFT | BD17: 45011.58-50011.58 | BE17: 77139.023
D18: 500-549 | E18: 958 | J18: Row Labels | K18: Sum of NumOfProducts | S18: 80011.58-85011.58 | T18: 181 | AK18: France | AL18: 0.39726027 | AM18: 0.39726027 | AP18: Row Labels | AQ18: Count of Exited | AV18: ACTIVITY VS LEFY | BD18: 50011.58-55011.58 | BE18: 79113.198
D19: 550-599 | E19: 1444 | J19: 18-27 | K19: 1578 | S19: 75011.58-80011.58 | T19: 179 | AK19: Spain | AL19: 0.20205479 | AM19: 0.20205479 | AP19: DIAMOND | AQ19: 2507 | AV19: Count of IsActiveMember | AW19: Column Labels | BD19: 55011.58-60011.58 | BE19: 74522.222
D20: 600-649 | E20: 1866 | J20: 28-37 | K20: 6281 | S20: 65011.58-70011.58 | T20: 179 | AK20: Grand Total | AL20: 1 | AM20: 1 | AP20: GOLD | AQ20: 2502 | AV20: Row Labels | AW20: NO | AX20: YES | AY20: Grand Total | BD20: 60011.58-65011.58 | BE20: 82650.77
D21: 650-699 | E21: 1952 | J21: 38-47 | K21: 4900 | S21: 195011.58-200011.58 | T21: 179 | AP21: PLATINUM | AQ21: 2495 | AV21: NO | AW21: 3546 | AX21: 4416 | AY21: 7962 | BD21: 65011.58-70011.58 | BE21: 74110.04
D22: 700-749 | E22: 1525 | J22: 48-57 | K22: 1570 | S22: 140011.58-145011.58 | T22: 178 | AP22: SILVER | AQ22: 2496 | AV22: YES | AW22: 1303 | AX22: 735 | AY22: 2038 | BD22: 70011.58-75011.58 | BE22: 81327.135
D23: 750-799 | E23: 968 | J23: 58-67 | K23: 681 | S23: 145011.58-150011.58 | T23: 178 | AP23: Grand Total | AQ23: 10000 | AV23: Grand Total | AW23: 4849 | AX23: 5151 | AY23: 10000 | BD23: 75011.58-80011.58 | BE23: 76343.922
D24: 800-850 | E24: 655 | J24: 68-77 | K24: 256 | S24: 50011.58-55011.58 | T24: 178 | BD24: 80011.58-85011.58 | BE24: 69762.4
D25: Grand Total | E25: 10000 | J25: 78-87 | K25: 31 | S25: 130011.58-135011.58 | T25: 176 | BD25: 85011.58-90011.58 | BE25: 79184.06
J26: 88-97 | K26: 5 | S26: 135011.58-140011.58 | T26: 176 | BD26: 90011.58-95011.58 | BE26: 74448.438
J27: Grand Total | K27: 15302 | S27: 160011.58-165011.58 | T27: 176 | BD27: 95011.58-100011.58 | BE27: 70009.339
S28: 30011.58-35011.58 | T28: 176 | BD28: 100011.58-105011.58 | BE28: 78459.632
S29: 15011.58-20011.58 | T29: 176 | BD29: 105011.58-110011.58 | BE29: 76928.812
S30: 180011.58-185011.58 | T30: 175 | BD30: 110011.58-115011.58 | BE30: 74019.425
S31: 40011.58-45011.58 | T31: 175 | BD31: 115011.58-120011.58 | BE31: 78493.604
S32: 120011.58-125011.58 | T32: 175 | BD32: 120011.58-125011.58 | BE32: 77530.515
S33: 105011.58-110011.58 | T33: 175 | BD33: 125011.58-130011.58 | BE33: 78903.281
S34: 190011.58-195011.58 | T34: 174 | BD34: 130011.58-135011.58 | BE34: 74242.324
S35: 85011.58-90011.58 | T35: 171 | BD35: 135011.58-140011.58 | BE35: 81106.413
S36: 35011.58-40011.58 | T36: 168 | BD36: 140011.58-145011.58 | BE36: 71117.502
S37: 10011.58-15011.58 | T37: 167 | BD37: 145011.58-150011.58 | BE37: 80517.598
S38: 155011.58-160011.58 | T38: 163 | BD38: 150011.58-155011.58 | BE38: 78416.493
S39: 185011.58-190011.58 | T39: 161 | BD39: 155011.58-160011.58 | BE39: 77203.632
... S45: 110011.58-115011.58 | T45: 156 | BD45: 185011.58-190011.58 | BE45: 76412.949
BD46: 190011.58-195011.58 | BE46: 81569.661
BD47: 195011.58-200011.58 | BE47: 76868.926
...

Sheet DASHBOARD
